## 手动抛异常 throw

### throw 例子

```cs
// IndexOutOfRangeException 是超出数组索引范围的异常
throw new IndexOutOfRangeException();
```

### 常见异常类

| 异常类型 | 描述 | 示例 |
| --- | --- | --- |
| [Exception](https://learn.microsoft.com/zh-cn/dotnet/api/system.exception) | 所有异常的基类。 | 无（使用此异常的派生类）。 |
| [IndexOutOfRangeException](https://learn.microsoft.com/zh-cn/dotnet/api/system.indexoutofrangeexception) | 仅当错误地对数组进行索引时，才由运行时引发。 | 在数组的有效范围外对数组进行索引：<br/>`arr[arr.Length+1]` |
| [NullReferenceException](https://learn.microsoft.com/zh-cn/dotnet/api/system.nullreferenceexception) | 仅当引用 null 对象时，才由运行时引发。 | `object o = null;`<br/>`o.ToString();` |
| [InvalidOperationException](https://learn.microsoft.com/zh-cn/dotnet/api/system.invalidoperationexception) | 当处于无效状态时，由方法引发。 | 从基础集合删除项后调用`Enumerator.MoveNext()`。 |
| [ArgumentException](https://learn.microsoft.com/zh-cn/dotnet/api/system.argumentexception) | 所有自变量异常的基类。 | 无（使用此异常的派生类）。 |
| [ArgumentNullException](https://learn.microsoft.com/zh-cn/dotnet/api/system.argumentnullexception) | 由不允许参数为 null 的方法引发。 | `String s = null;`<br/>`"Calculate".IndexOf(s);` |
| [ArgumentOutOfRangeException](https://learn.microsoft.com/zh-cn/dotnet/api/system.argumentoutofrangeexception) | 由验证自变量是否位于给定范围内的方法引发。 | `String s = "string";`<br/>`s.Substring(s.Length+1);` |

### 参考文档：

[在 .NET 中处理和引发异常](https://learn.microsoft.com/zh-cn/dotnet/standard/exceptions/)

[throw](https://learn.microsoft.com/zh-cn/dotnet/csharp/language-reference/keywords/throw)

[如何：显式抛出异常](https://learn.microsoft.com/zh-cn/dotnet/standard/exceptions/how-to-explicitly-throw-exceptions)

## try-finally

发生异常 finally 块将不会执行，程序终止。所以考虑异常情况还是需要 catch 块。

更多信息：[try-finally](https://learn.microsoft.com/zh-cn/dotnet/csharp/language-reference/keywords/try-finally)

## try-catch-finally

更多信息：[try-catch-finally](https://learn.microsoft.com/zh-cn/dotnet/csharp/language-reference/keywords/try-catch-finally)

## finally 块作用

既然发生异常如果没有使用 catch，finally 块也不会执行。那么，还要 finally 干嘛呢？？其实不是的， finally 主要解决 try 或 catch 中包括 return 的情况。在 try 或 catch 中包括 return 时，finally 块后面是不会执行的，但 finally 块会执行。

参考文档：[C# try-catch-finally 的 finally 的作用是什么？](https://blog.csdn.net/P_newbie/article/details/106082028)
