
## throw 手动抛异常

手动让程序报错，程序将终止

### 语法

```
throw expression;
```
expression 任意表达式

### 示例

```
throw "Error2"; // 抛出了一个值为字符串的异常
// 后面的代码不会执行

throw 42;       // 抛出了一个值为整数42的异常
throw true;     // 抛出了一个值为true的异常
```

## 异常捕获

阻止程序异常终止运行

```
// 捕获自定义异常
try {
  throw '错误1'
} catch(e) {
  console.log(e) // '错误1'
}

// 捕获程序异常。将抛出一个 Error 对象
try {
  a
} catch(e) {
  console.log(e) // 一个 Error 对象
}

```

## Error

能给出代码位置信息(stack)

```js
console.dir(new Error('test'))
```

Error 子类

- EvalError: raised when an error occurs executing code in eval() 
- RangeError: raised when a numeric variable or parameter is outside of its valid range 
- ReferenceError: raised when de-referencing an invalid reference 
- SyntaxError: raised when a syntax error occurs while parsing code in eval() 
- TypeError: raised when a variable or parameter is not a valid type 
- URIError: raised when encodeURI() or decodeURI() are passed invalid parameters


## try catch 是否可捕获函数中的错误
方法内部有错误，try 中执行此方法，能捕捉到此错误吗？答案是可以

也就是说，只要在入口处 try catch，就可以保证程序不会中断运行了

```js
function test () {
  testChild()
}

function testChild () {
  throw new Error('err')
}

try {
  test()
}
catch (err) {
  console.log(err)
}

```

